{"success":false,"status_code":500,"error":"An error occurred","traceback":"Traceback (most recent call last):\n  File \"/home/GetLinkBackend/venv/lib/python3.12/site-packages/django/db/backends/utils.py\", line 105, in _execute\n    return self.cursor.execute(sql, params)\n           ^^^^^^^^^^^^^^^^^^^^^^^^^^^^^^^^\npsycopg2.errors.UndefinedColumn: column assessment_result.fixed_completion_time does not exist\nLINE 1: ..., \"assessment_result\".\"expected_completion_time\", \"assessmen...\n                                                             ^\n\n\nThe above exception was the direct cause of the following exception:\n\nTraceback (most recent call last):\n  File \"/home/GetLinkBackend/helpers/utils/advice.py\", line 30, in wrapper\n    return func(*args, **kwargs)\n           ^^^^^^^^^^^^^^^^^^^^^\n  File \"/home/GetLinkBackend/assessment/views.py\", line 2372, in post\n    result = Result.objects.get(id=result_id)\n             ^^^^^^^^^^^^^^^^^^^^^^^^^^^^^^^^\n  File \"/home/GetLinkBackend/venv/lib/python3.12/site-packages/django/db/models/manager.py\", line 87, in manager_method\n    return getattr(self.get_queryset(), name)(*args, **kwargs)\n           ^^^^^^^^^^^^^^^^^^^^^^^^^^^^^^^^^^^^^^^^^^^^^^^^^^^\n  File \"/home/GetLinkBackend/venv/lib/python3.12/site-packages/django/db/models/query.py\", line 645, in get\n    num = len(clone)\n          ^^^^^^^^^^\n  File \"/home/GetLinkBackend/venv/lib/python3.12/site-packages/django/db/models/query.py\", line 382, in __len__\n    self._fetch_all()\n  File \"/home/GetLinkBackend/venv/lib/python3.12/site-packages/django/db/models/query.py\", line 1928, in _fetch_all\n    self._result_cache = list(self._iterable_class(self))\n                         ^^^^^^^^^^^^^^^^^^^^^^^^^^^^^^^^\n  File \"/home/GetLinkBackend/venv/lib/python3.12/site-packages/django/db/models/query.py\", line 91, in __iter__\n    results = compiler.execute_sql(\n              ^^^^^^^^^^^^^^^^^^^^^\n  File \"/home/GetLinkBackend/venv/lib/python3.12/site-packages/django/db/models/sql/compiler.py\", line 1574, in execute_sql\n    cursor.execute(sql, params)\n  File \"/home/GetLinkBackend/venv/lib/python3.12/site-packages/django/db/backends/utils.py\", line 122, in execute\n    return super().execute(sql, params)\n           ^^^^^^^^^^^^^^^^^^^^^^^^^^^^\n  File \"/home/GetLinkBackend/venv/lib/python3.12/site-packages/sentry_sdk/utils.py\", line 1786, in runner\n    return sentry_patched_function(*args, **kwargs)\n           ^^^^^^^^^^^^^^^^^^^^^^^^^^^^^^^^^^^^^^^^\n  File \"/home/GetLinkBackend/venv/lib/python3.12/site-packages/sentry_sdk/integrations/django/__init__.py\", line 653, in execute\n    result = real_execute(self, sql, params)\n             ^^^^^^^^^^^^^^^^^^^^^^^^^^^^^^^\n  File \"/home/GetLinkBackend/venv/lib/python3.12/site-packages/django/db/backends/utils.py\", line 79, in execute\n    return self._execute_with_wrappers(\n           ^^^^^^^^^^^^^^^^^^^^^^^^^^^^\n  File \"/home/GetLinkBackend/venv/lib/python3.12/site-packages/django/db/backends/utils.py\", line 92, in _execute_with_wrappers\n    return executor(sql, params, many, context)\n           ^^^^^^^^^^^^^^^^^^^^^^^^^^^^^^^^^^^^\n  File \"/home/GetLinkBackend/venv/lib/python3.12/site-packages/django/db/backends/utils.py\", line 100, in _execute\n    with self.db.wrap_database_errors:\n  File \"/home/GetLinkBackend/venv/lib/python3.12/site-packages/django/db/utils.py\", line 91, in __exit__\n    raise dj_exc_value.with_traceback(traceback) from exc_value\n  File \"/home/GetLinkBackend/venv/lib/python3.12/site-packages/django/db/backends/utils.py\", line 105, in _execute\n    return self.cursor.execute(sql, params)\n           ^^^^^^^^^^^^^^^^^^^^^^^^^^^^^^^^\ndjango.db.utils.ProgrammingError: column assessment_result.fixed_completion_time does not exist\nLINE 1: ..., \"assessment_result\".\"expected_completion_time\", \"assessmen...\n                                                             ^\n\n"}