{"message":"Something went wrong, try again!","success":false,"response":{"traceback":"Traceback (most recent call last):\n  File \"/home/GetLinkBackend/helpers/utils/advice.py\", line 25, in wrapper\n    return func(*args, **kwargs)\n           ^^^^^^^^^^^^^^^^^^^^^\n  File \"/home/GetLinkBackend/assessment/views.py\", line 3185, in post\n    serializer.save()\n  File \"/home/GetLinkBackend/venv/lib/python3.12/site-packages/rest_framework/serializers.py\", line 203, in save\n    self.instance = self.update(self.instance, validated_data)\n                    ^^^^^^^^^^^^^^^^^^^^^^^^^^^^^^^^^^^^^^^^^^\n  File \"/home/GetLinkBackend/venv/lib/python3.12/site-packages/rest_framework/serializers.py\", line 1033, in update\n    instance.save()\n  File \"/home/GetLinkBackend/assessment/models.py\", line 986, in save\n    from assessment.task import process_plain_answer\nImportError: cannot import name 'process_plain_answer' from 'assessment.task' (/home/GetLinkBackend/assessment/task.py)\n"}}